2018-09-05 18:00:01,771 DEBU root Last attempt: 2018-09-05T12:00:01Z
2018-09-05 18:00:01,772 DEBU root Last success: 2018-09-05T12:00:01Z
2018-09-05 18:00:01,772 INFO root Writing last-update file
2018-09-05 18:00:01,772 INFO root Query: 'collection:archivebot oai_updatedate:[2018-09-05T12:00:01Z TO null]'
Traceback (most recent call last):
  File "/usr/lib/python3/dist-packages/urllib3/connectionpool.py", line 391, in _make_request
    six.raise_from(e, None)
  File "<string>", line 2, in raise_from
  File "/usr/lib/python3/dist-packages/urllib3/connectionpool.py", line 387, in _make_request
    httplib_response = conn.getresponse()
  File "/usr/lib/python3.5/http/client.py", line 1198, in getresponse
    response.begin()
  File "/usr/lib/python3.5/http/client.py", line 297, in begin
    version, status, reason = self._read_status()
  File "/usr/lib/python3.5/http/client.py", line 258, in _read_status
    line = str(self.fp.readline(_MAXLINE + 1), "iso-8859-1")
  File "/usr/lib/python3.5/socket.py", line 576, in readinto
    return self._sock.recv_into(b)
  File "/usr/lib/python3.5/ssl.py", line 937, in recv_into
    return self.read(nbytes, buffer)
  File "/usr/lib/python3.5/ssl.py", line 799, in read
    return self._sslobj.read(len, buffer)
  File "/usr/lib/python3.5/ssl.py", line 583, in read
    v = self._sslobj.read(len, buffer)
socket.timeout: The read operation timed out

During handling of the above exception, another exception occurred:

Traceback (most recent call last):
  File "/usr/lib/python3/dist-packages/urllib3/connectionpool.py", line 594, in urlopen
    chunked=chunked)
  File "/usr/lib/python3/dist-packages/urllib3/connectionpool.py", line 393, in _make_request
    self._raise_timeout(err=e, url=url, timeout_value=read_timeout)
  File "/usr/lib/python3/dist-packages/urllib3/connectionpool.py", line 313, in _raise_timeout
    raise ReadTimeoutError(self, url, "Read timed out. (read timeout=%s)" % timeout_value)
requests.packages.urllib3.exceptions.ReadTimeoutError: HTTPSConnectionPool(host='archive.org', port=443): Read timed out. (read timeout=12)

During handling of the above exception, another exception occurred:

Traceback (most recent call last):
  File "/home/archivebot-archives/.local/lib/python3.5/site-packages/internetarchive/session.py", line 250, in get_metadata
    resp = self.get(url, **request_kwargs)
  File "/usr/lib/python3/dist-packages/requests/sessions.py", line 501, in get
    return self.request('GET', url, **kwargs)
  File "/usr/lib/python3/dist-packages/requests/sessions.py", line 488, in request
    resp = self.send(prep, **send_kwargs)
  File "/home/archivebot-archives/.local/lib/python3.5/site-packages/internetarchive/session.py", line 368, in send
    r = super(ArchiveSession, self).send(request, **kwargs)
  File "/usr/lib/python3/dist-packages/requests/sessions.py", line 609, in send
    r = adapter.send(request, **kwargs)
  File "/usr/lib/python3/dist-packages/requests/adapters.py", line 423, in send
    timeout=timeout
  File "/usr/lib/python3/dist-packages/urllib3/connectionpool.py", line 643, in urlopen
    _stacktrace=sys.exc_info()[2])
  File "/usr/lib/python3/dist-packages/urllib3/util/retry.py", line 315, in increment
    total -= 1
TypeError: unsupported operand type(s) for -=: 'Retry' and 'int'

During handling of the above exception, another exception occurred:

Traceback (most recent call last):
  File "/home/archivebot-archives/archivebot-archives/code/update.py", line 101, in <module>
    for i in internetarchive.search_items(query, request_kwargs = {'timeout': 60}).iter_as_items(): #TODO: add max_retries
  File "/home/archivebot-archives/.local/lib/python3.5/site-packages/internetarchive/search.py", line 204, in __next__
    return self.iterator.__next__()
  File "/home/archivebot-archives/.local/lib/python3.5/site-packages/internetarchive/search.py", line 173, in _get_item_from_search_result
    return self.session.get_item(search_result['identifier'])
  File "/home/archivebot-archives/.local/lib/python3.5/site-packages/internetarchive/session.py", line 227, in get_item
    item_metadata = self.get_metadata(identifier, request_kwargs)
  File "/home/archivebot-archives/.local/lib/python3.5/site-packages/internetarchive/session.py", line 255, in get_metadata
    raise type(exc)(error_msg)
TypeError: Error retrieving metadata from https://archive.org/metadata/archiveteam_archivebot_go_20180904190002, unsupported operand type(s) for -=: 'Retry' and 'int'
